/Users/rohanmehta/anaconda3/envs/jax/lib/python3.11/site-packages/haliax/nn/__init__.py:159: UserWarning: target_y has dtype uint8, which is not a floating point type. This is probably a mistake.
  warnings.warn(
Traceback (most recent call last):
  File "/Users/rohanmehta/Desktop/ML Projects/GPT_nano/train.py", line 399, in <module>
    main()
  File "/Users/rohanmehta/anaconda3/envs/jax/lib/python3.11/site-packages/draccus/argparsing.py", line 182, in wrapper_inner
    response = fn(cfg, *args, **kwargs)
               ^^^^^^^^^^^^^^^^^^^^^^^^
  File "/Users/rohanmehta/Desktop/ML Projects/GPT_nano/train.py", line 396, in main
    trainer.train()
  File "/Users/rohanmehta/Desktop/ML Projects/GPT_nano/train.py", line 361, in train
    dt = t1 - t0
              ^^
UnboundLocalError: cannot access local variable 't0' where it is not associated with a value
Traceback (most recent call last):
  File "/Users/rohanmehta/Desktop/ML Projects/GPT_nano/train.py", line 399, in <module>
    main()
  File "/Users/rohanmehta/anaconda3/envs/jax/lib/python3.11/site-packages/draccus/argparsing.py", line 182, in wrapper_inner
    response = fn(cfg, *args, **kwargs)
               ^^^^^^^^^^^^^^^^^^^^^^^^
  File "/Users/rohanmehta/Desktop/ML Projects/GPT_nano/train.py", line 396, in main
    trainer.train()
  File "/Users/rohanmehta/Desktop/ML Projects/GPT_nano/train.py", line 361, in train
    dt = t1 - t0
              ^^
UnboundLocalError: cannot access local variable 't0' where it is not associated with a value
Step: 0 | Average Train Loss: 200634496.00 | Average Val Loss: 195769936.00
Saving checkpoint to